2022-08-25 13:56:04 DEBUG:busco.run_BUSCO	Command line: /home/mike/miniconda3/envs/busco/bin/busco
2022-08-25 13:56:04 INFO:busco.run_BUSCO	***** Start a BUSCO v5.4.2 analysis, current time: 08/25/2022 13:56:04 *****
2022-08-25 13:56:04 DEBUG:busco.ConfigManager	Getting config file
2022-08-25 13:56:04 INFO:busco.ConfigManager	Configuring BUSCO with local environment
2022-08-25 13:56:04 WARNING:busco.BuscoConfig	Running Auto Lineage Selector as no lineage dataset was specified. This will take a little longer than normal. If you know what lineage dataset you want to use, please specify this in the config file or using the -l (--lineage-dataset) flag in the command line.
2022-08-25 13:56:04 ERROR:busco.BuscoRunner	The parameter "in (--in)" was not provided. Please add it in the config file or provide it through the command line
2022-08-25 13:56:04 DEBUG:busco.BuscoRunner	The parameter "in (--in)" was not provided. Please add it in the config file or provide it through the command line
Traceback (most recent call last):
  File "/home/mike/miniconda3/envs/busco/lib/python3.7/configparser.py", line 788, in get
    value = d[option]
  File "/home/mike/miniconda3/envs/busco/lib/python3.7/collections/__init__.py", line 916, in __getitem__
    return self.__missing__(key)            # support subclasses that define __missing__
  File "/home/mike/miniconda3/envs/busco/lib/python3.7/collections/__init__.py", line 908, in __missing__
    raise KeyError(key)
KeyError: 'in'

During handling of the above exception, another exception occurred:

Traceback (most recent call last):
  File "/home/mike/miniconda3/envs/busco/lib/python3.7/site-packages/busco/BuscoConfig.py", line 615, in _check_mandatory_keys_exist
    value = self.get("busco_run", param)
  File "/home/mike/miniconda3/envs/busco/lib/python3.7/configparser.py", line 791, in get
    raise NoOptionError(option, section)
configparser.NoOptionError: No option 'in' in section: 'busco_run'

During handling of the above exception, another exception occurred:

Traceback (most recent call last):
  File "/home/mike/miniconda3/envs/busco/lib/python3.7/site-packages/busco/run_BUSCO.py", line 70, in run
    self.load_config()
  File "/home/mike/miniconda3/envs/busco/lib/python3.7/site-packages/busco/run_BUSCO.py", line 62, in load_config
    self.config_manager.load_busco_config_main()
  File "/home/mike/miniconda3/envs/busco/lib/python3.7/site-packages/busco/BuscoLogger.py", line 62, in wrapped_func
    self.retval = func(*args, **kwargs)
  File "/home/mike/miniconda3/envs/busco/lib/python3.7/site-packages/busco/ConfigManager.py", line 58, in load_busco_config_main
    self.config_main.validate()
  File "/home/mike/miniconda3/envs/busco/lib/python3.7/site-packages/busco/BuscoConfig.py", line 524, in validate
    self._check_mandatory_keys_exist()
  File "/home/mike/miniconda3/envs/busco/lib/python3.7/site-packages/busco/BuscoLogger.py", line 58, in wrapped_func
    self.retval = func(*args, **kwargs)
  File "/home/mike/miniconda3/envs/busco/lib/python3.7/site-packages/busco/BuscoConfig.py", line 677, in _check_mandatory_keys_exist
    "through the command line".format(param, param)
busco.Exceptions.BatchFatalError: The parameter "in (--in)" was not provided. Please add it in the config file or provide it through the command line
2022-08-25 13:56:04 ERROR:busco.BuscoRunner	BUSCO analysis failed!
2022-08-25 13:56:04 ERROR:busco.BuscoRunner	Check the logs, read the user guide (https://busco.ezlab.org/busco_userguide.html), and check the BUSCO issue board on https://gitlab.com/ezlab/busco/issues

